Workbook

Sheet The Worksheet
A1: Course Name | B1: Owning faculty | C1: Course code | D1: Relationship type | E1: Curriculum Item | G1: Description
G2: <p>This course is part of an articulated program made up of the Graduate Certificate in High Performance Sport (<a href="https://handbook.uts.edu.au/courses/c11267.html">C11267</a>), the Graduate Diploma in High Performance Sport (<a href="https://handbook.uts.edu.au/courses/c07130.html">C07130</a>), and the Master of High Performance Sport (<a 4href="https://handbook.uts.edu.au/courses/c04362.html">C04362</a>).</p>
G4: <p>This course is part of an articulated program made up of the Graduate Certificate in High Performance Sport (<a href="https://handbook.uts.edu.au/courses/c11267.html">C11267</a>), the Graduate Diploma in High Performance Sport (<a href="https://handbook.uts.edu.au/courses/c07130.html">C07130</a>), and the Master of High Performance Sport (<a href="https://handbook.uts.edu.au/courses/c04362.html">C04362</a>).</p>
A5: =VLOOKUP('The Worksheet'!C5,Table1[#All],2,FALSE) -> Graduate Diploma in High Performance Sport | B5: =VLOOKUP('The Worksheet'!C5,Table1[#All],3,FALSE) -> J | C5: C07130 | D5: articulated course | E5: C11267 | G5: <p>This course is articulated with the Graduate Certificate in High Performance Sport (<a href="https://handbook.uts.edu.au/courses/c11267.html">C11267</a>).</p>
A6: =VLOOKUP('The Worksheet'!C6,Table1[#All],2,FALSE) -> Graduate Diploma in High Performance Sport | B6: =VLOOKUP('The Worksheet'!C6,Table1[#All],3,FALSE) -> J | C6: C07130 | D6: articulated course | E6: c04362 | G6: <p>This course is articulated with the Master of High Performance Sport (<a href="https://handbook.uts.edu.au/courses/c04362.html">C04362</a>).</p>
A7: =VLOOKUP('The Worksheet'!C7,Table1[#All],2,FALSE) -> Graduate Certificate in High Performance Sport | B7: =VLOOKUP('The Worksheet'!C7,Table1[#All],3,FALSE) -> J | C7: C11267 | D7: articulated course | E7: C07130 | G7: <p>This course is part of an articulated program made up of the Graduate Certificate in High Performance Sport (<a href="https://handbook.uts.edu.au/courses/c11267.html">C11267</a>), the Graduate Diploma in High Performance Sport (<a href="https://handbook.uts.edu.au/courses/c07130.html">C07130</a>), and the Master of High Performance Sport (<a href="https://handbook.uts.edu.au/courses/c04362.html">C04362</a>). </p>
A8: =VLOOKUP('The Worksheet'!C8,Table1[#All],2,FALSE) -> Graduate Certificate in High Performance Sport | B8: =VLOOKUP('The Worksheet'!C8,Table1[#All],3,FALSE) -> J | C8: C11267 | D8: articulated course | E8: c04362 | G8: <p>This course is part of an articulated program made up of the Graduate Certificate in High Performance Sport (<a href="https://handbook.uts.edu.au/courses/c11267.html">C11267</a>), the Graduate Diploma in High Performance Sport (<a href="https://handbook.uts.edu.au/courses/c07130.html">C07130</a>), and the Master of High Performance Sport (<a href="https://handbook.uts.edu.au/courses/c04362.html">C04362</a>).</p>
A9: =VLOOKUP('The Worksheet'!C9,Table1[#All],2,FALSE) -> Master of High Performance Sport | B9: =VLOOKUP('The Worksheet'!C9,Table1[#All],3,FALSE) -> J | C9: c04362 | D9: articulated course | E9: C07130 | G9: <p>This course is part of an articulated program made up of the Graduate Certificate in High Performance Sport (<a href="https://handbook.uts.edu.au/courses/c11267.html">C11267</a>), the Graduate Diploma in High Performance Sport (<a href="https://handbook.uts.edu.au/courses/c07130.html">C07130</a>), and the Master of High Performance Sport (<a href="https://handbook.uts.edu.au/courses/c04362.html">C04362</a>).</p>
A10: =VLOOKUP('The Worksheet'!C10,Table1[#All],2,FALSE) -> Master of High Performance Sport | B10: =VLOOKUP('The Worksheet'!C10,Table1[#All],3,FALSE) -> J | C10: c04362 | D10: articulated course | E10: C11267 | G10: <p>This course is part of an articulated program made up of the Graduate Certificate in High Performance Sport (<a href="https://handbook.uts.edu.au/courses/c11267.html">C11267</a>), the Graduate Diploma in High Performance Sport (<a href="https://handbook.uts.edu.au/courses/c07130.html">C07130</a>), and the Master of High Performance Sport (<a href="https://handbook.uts.edu.au/courses/c04362.html">C04362</a>).</p>
A11: =VLOOKUP('The Worksheet'!C11,Table1[#All],2,FALSE) -> #N/A | B11: =VLOOKUP('The Worksheet'!C11,Table1[#All],3,FALSE) -> #N/A | G11: p>This exit-only course is part of an articulated program comprising the Graduate Certificate in Engineering (<a href="/courses/c11236.html">C11236</a>), the Graduate Diploma in Engineering, the Master of Engineering (<a href="/courses/c04271.html">C04271</a>), the Master of Engineering (Extension) (<a href="/courses/c04277.html">C04277</a>), the Master of Engineering (Advanced) (<a href="/courses/c04278.html">C04278</a>) and the Master of Engineering Master of Engineering Management (<a href="/courses/c04273.html">C04273</a>).</p>
A12: =VLOOKUP('The Worksheet'!C12,Table1[#All],2,FALSE) -> #N/A | B12: =VLOOKUP('The Worksheet'!C12,Table1[#All],3,FALSE) -> #N/A
A13: =VLOOKUP('The Worksheet'!C13,Table1[#All],2,FALSE) -> Graduate Diploma in Engineering | B13: =VLOOKUP('The Worksheet'!C13,Table1[#All],3,FALSE) -> D | C13: C06108 | D13: exit course | E13: C04271 | G13: Graduate diploma In Engineering(C06108) is exit only course for Master of Engineering (<a href="/courses/c04271.html">C04271</a>)
A14: =VLOOKUP('The Worksheet'!C14,Table1[#All],2,FALSE) -> Graduate Diploma in Engineering | B14: =VLOOKUP('The Worksheet'!C14,Table1[#All],3,FALSE) -> D | C14: C06108 | D14: exit course | E14: C04278 | G14: Graduate diploma In Engineering(C06108) is exit only course for Master of Engineering(Advanced) (<a href="/courses/c04278.html">C04278</a>)
A15: =VLOOKUP('The Worksheet'!C15,Table1[#All],2,FALSE) -> Graduate Diploma in Engineering | B15: =VLOOKUP('The Worksheet'!C15,Table1[#All],3,FALSE) -> D | C15: C06108 | D15: exit course | E15: C04277 | G15: ME exten
A16: =VLOOKUP('The Worksheet'!C16,Table1[#All],2,FALSE) -> Graduate Diploma in Engineering | B16: =VLOOKUP('The Worksheet'!C16,Table1[#All],3,FALSE) -> D | C16: C06108 | D16: exit course | E16: c04273 | G16: he Master of Engineering Master of Engineering Management
A17: =VLOOKUP('The Worksheet'!C17,Table1[#All],2,FALSE) -> Graduate Diploma in Engineering | B17: =VLOOKUP('The Worksheet'!C17,Table1[#All],3,FALSE) -> D | C17: C06108 | D17: articulated course | E17: C11236 | G17: Graduate Certificate in Engineering
A18: =VLOOKUP('The Worksheet'!C18,Table1[#All],2,FALSE) -> Graduate Diploma in Engineering | B18: =VLOOKUP('The Worksheet'!C18,Table1[#All],3,FALSE) -> D | C18: C06108 | D18: articulated course | E18: C04278 | G18: ME adv
A19: =VLOOKUP('The Worksheet'!C19,Table1[#All],2,FALSE) -> Graduate Diploma in Engineering | B19: =VLOOKUP('The Worksheet'!C19,Table1[#All],3,FALSE) -> D | C19: C06108 | D19: articulated course | E19: C04277 | G19: ME exten
A20: =VLOOKUP('The Worksheet'!C20,Table1[#All],2,FALSE) -> Graduate Diploma in Engineering | B20: =VLOOKUP('The Worksheet'!C20,Table1[#All],3,FALSE) -> D | C20: C06108 | D20: articulated course | E20: c04273 | G20: he Master of Engineering Master of Engineering Management
A21: =VLOOKUP('The Worksheet'!C21,Table1[#All],2,FALSE) -> Master of Engineering | B21: =VLOOKUP('The Worksheet'!C21,Table1[#All],3,FALSE) -> D | C21: C04271 | D21: articulated course | E21: c11236 | F21: =VLOOKUP(E21,Table1[#All],2,FALSE) -> Graduate Certificate in Engineering | G21: Grad certi
A22: =VLOOKUP('The Worksheet'!C22,Table1[#All],2,FALSE) -> Master of Engineering | B22: =VLOOKUP('The Worksheet'!C22,Table1[#All],3,FALSE) -> D | C22: C04271 | D22: articulated course | E22: C04278 | F22: =VLOOKUP(E22,Table1[#All],2,FALSE) -> Master of Engineering (Advanced) | G22: ME adv
A23: =VLOOKUP('The Worksheet'!C23,Table1[#All],2,FALSE) -> Master of Engineering | B23: =VLOOKUP('The Worksheet'!C23,Table1[#All],3,FALSE) -> D | C23: C04271 | D23: articulated course | E23: C04277 | F23: =VLOOKUP(E23,Table1[#All],2,FALSE) -> Master of Engineering (Extension) | G23: ME exten
A24: =VLOOKUP('The Worksheet'!C24,Table1[#All],2,FALSE) -> Master of Engineering | B24: =VLOOKUP('The Worksheet'!C24,Table1[#All],3,FALSE) -> D | C24: C04271 | D24: articulated course | E24: C06108 | F24: =VLOOKUP(E24,Table1[#All],2,FALSE) -> Graduate Diploma in Engineering | G24: Grad dip
A25: =VLOOKUP('The Worksheet'!C25,Table1[#All],2,FALSE) -> Master of Engineering (Advanced) | B25: =VLOOKUP('The Worksheet'!C25,Table1[#All],3,FALSE) -> D | C25: C04278 | D25: articulated course | E25: C04277 | F25: =VLOOKUP(E25,Table1[#All],2,FALSE) -> Master of Engineering (Extension) | G25: ME exten
A26: =VLOOKUP('The Worksheet'!C26,Table1[#All],2,FALSE) -> Master of Engineering (Advanced) | B26: =VLOOKUP('The Worksheet'!C26,Table1[#All],3,FALSE) -> D | C26: C04278 | D26: articulated course | E26: C06108 | F26: =VLOOKUP(E26,Table1[#All],2,FALSE) -> Graduate Diploma in Engineering | G26: Grad dip
A27: =VLOOKUP('The Worksheet'!C27,Table1[#All],2,FALSE) -> Master of Engineering (Advanced) | B27: =VLOOKUP('The Worksheet'!C27,Table1[#All],3,FALSE) -> D | C27: C04278 | D27: articulated course | E27: c04273 | F27: =VLOOKUP(E27,Table1[#All],2,FALSE) -> Master of Engineering Master of Engineering Management | G27: he Master of Engineering Master of Engineering Management
A28: =VLOOKUP('The Worksheet'!C28,Table1[#All],2,FALSE) -> Master of Engineering (Advanced) | B28: =VLOOKUP('The Worksheet'!C28,Table1[#All],3,FALSE) -> D | C28: C04278 | D28: articulated course | E28: C04271 | F28: =VLOOKUP(E28,Table1[#All],2,FALSE) -> Master of Engineering | G28: Master of Engineering
A29: =VLOOKUP('The Worksheet'!C29,Table1[#All],2,FALSE) -> Master of Engineering (Advanced) | B29: =VLOOKUP('The Worksheet'!C29,Table1[#All],3,FALSE) -> D | C29: C04278 | D29: articulated course | E29: c11236 | F29: =VLOOKUP(E29,Table1[#All],2,FALSE) -> Graduate Certificate in Engineering | G29: Grad certi
A30: =VLOOKUP('The Worksheet'!C30,Table1[#All],2,FALSE) -> Master of Engineering (Extension) | B30: =VLOOKUP('The Worksheet'!C30,Table1[#All],3,FALSE) -> D | C30: C04277 | D30: articulated course | E30: C06108 | F30: =VLOOKUP(E30,Table1[#All],2,FALSE) -> Graduate Diploma in Engineering | G30: Grad dip
A31: =VLOOKUP('The Worksheet'!C31,Table1[#All],2,FALSE) -> Master of Engineering (Extension) | B31: =VLOOKUP('The Worksheet'!C31,Table1[#All],3,FALSE) -> D | C31: C04277 | D31: articulated course | E31: C04271 | F31: =VLOOKUP(E31,Table1[#All],2,FALSE) -> Master of Engineering | G31: Master of Engineering
A32: =VLOOKUP('The Worksheet'!C32,Table1[#All],2,FALSE) -> Master of Engineering (Extension) | B32: =VLOOKUP('The Worksheet'!C32,Table1[#All],3,FALSE) -> D | C32: C04277 | D32: articulated course | E32: c11236 | F32: =VLOOKUP(E32,Table1[#All],2,FALSE) -> Graduate Certificate in Engineering | G32: Grad certi
... A52: =VLOOKUP('The Worksheet'!C52,Table1[#All],2,FALSE) -> Master of Engineering Master of Engineering Management | B52: =VLOOKUP('The Worksheet'!C52,Table1[#All],3,FALSE) -> D | C52: C04273 | D52: articulated course | E52: C04277 | F52: =VLOOKUP(E52,Table1[#All],2,FALSE) -> Master of Engineering (Extension) | G52: <p>This course is part of an articulated program comprising the Graduate Certificate in Engineering (<a href="/courses/c11236.html">C11236</a>), the Graduate Diploma in Engineering (<a href="/courses/c06108.html">C06108</a>), the Master of Engineering (<a href="/courses/c04271.html">C04271</a>), the Master of Engineering (Extension) (<a href="/courses/c04277.html">C04277</a>) and the Master of Engineering Master of Engineering Management.</p>
A53: =VLOOKUP('The Worksheet'!C53,Table1[#All],2,FALSE) -> Master of Engineering Management Master of Business Administration | B53: =VLOOKUP('The Worksheet'!C53,Table1[#All],3,FALSE) -> D | C53: C04274 | D53: articulated course | E53: c06110 | F53: =VLOOKUP(E53,Table1[#All],2,FALSE) -> Graduate Diploma in Engineering Management
A54: =VLOOKUP('The Worksheet'!C54,Table1[#All],2,FALSE) -> Master of Technology | B54: =VLOOKUP('The Worksheet'!C54,Table1[#All],3,FALSE) -> D | C54: C04406 | D54: articulated course | E54: C11301 | F54: =VLOOKUP(E54,Table1[#All],2,FALSE) -> Graduate Certificate in Technology
A55: =VLOOKUP('The Worksheet'!C55,Table1[#All],2,FALSE) -> Master of Technology | B55: =VLOOKUP('The Worksheet'!C55,Table1[#All],3,FALSE) -> D | C55: C04406 | D55: articulated course | E55: C06137 | F55: =VLOOKUP(E55,Table1[#All],2,FALSE) -> Graduate Diploma in Technology
A56: =VLOOKUP('The Worksheet'!C56,Table1[#All],2,FALSE) -> Graduate Certificate in Technology | B56: =VLOOKUP('The Worksheet'!C56,Table1[#All],3,FALSE) -> D | C56: C11301 | D56: articulated course | E56: C06137 | F56: =VLOOKUP(E56,Table1[#All],2,FALSE) -> Graduate Diploma in Technology
A57: =VLOOKUP('The Worksheet'!C57,Table1[#All],2,FALSE) -> Graduate Certificate in Technology | B57: =VLOOKUP('The Worksheet'!C57,Table1[#All],3,FALSE) -> D | C57: C11301 | D57: articulated course | E57: C04406 | F57: =VLOOKUP(E57,Table1[#All],2,FALSE) -> Master of Technology
A58: =VLOOKUP('The Worksheet'!C58,Table1[#All],2,FALSE) -> Graduate Diploma in Technology | B58: =VLOOKUP('The Worksheet'!C58,Table1[#All],3,FALSE) -> D | C58: C06137 | D58: articulated course | E58: C11301 | F58: =VLOOKUP(E58,Table1[#All],2,FALSE) -> Graduate Certificate in Technology
A59: =VLOOKUP('The Worksheet'!C59,Table1[#All],2,FALSE) -> Graduate Diploma in Technology | B59: =VLOOKUP('The Worksheet'!C59,Table1[#All],3,FALSE) -> D | C59: C06137 | D59: articulated course | E59: C04406 | F59: =VLOOKUP(E59,Table1[#All],2,FALSE) -> Master of Technology
A60: =VLOOKUP('The Worksheet'!C60,Table1[#All],2,FALSE) -> Master of Health Services Management | B60: =VLOOKUP('The Worksheet'!C60,Table1[#All],3,FALSE) -> J | C60: C04409 | D60: articulated course | E60: C11304 | F60: =VLOOKUP(E60,Table1[#All],2,FALSE) -> Graduate Certificate in Health Services Management
...

Sheet Ticking Off Sheet
A1: Academic Item | B1: Version Number | C1: Course Name | D1: Owning Faculty | E1: Relationship type | F1: Curriculum Item | G1: Description
A2: 10124 | B2: 2024.01 | E2: Articulated course | F2: 10124 | G2: Description text
A3: C01001 | B3: 2025.01 | C3: Doctor of Letters | D3: P
A4: C01002 | B4: 2025.01 | C4: Doctor of Fine Arts | D4: P
A5: C01003 | B5: 2025.01 | C5: Doctor of Science | D5: P
A6: C01004 | B6: 2025.01 | C6: Doctor of Laws | D6: P
A7: C42003 | B7: 2025.01 | C7: Business Postgraduate Cross - Institution | D7: B
A8: C42004 | B8: 2025.01 | C8: Design PG Cross Institution | D8: AD
A9: C42005 | B9: 2025.01 | C9: Engineering PG Cross-Institution | D9: D
A10: C42013 | B10: 2025.01 | C10: International Studies PG Cross-Institution | D10: G
A11: C50002 | B11: 2025.01 | C11: Non-Award | D11: P
A12: C30010 | B12: 2025.01 | C12: Supplementary Course for Aboriginal Students | D12: PA
A13: C41001 | B13: 2025.01 | C13: Architecture Cross UG Cross-Institution | D13: AA
A14: C41002 | B14: 2025.01 | C14: Building UG Cross-Institution | D14: AB
... A56: C41013 | B56: 2025.01 | C56: Health UG Cross-Institution | D56: J
A57: C06108 | B57: 2025.01 | C57: Graduate Diploma in Engineering | D57: D | G57: <p>This exit-only course is part of an articulated program comprising the Graduate Certificate in Engineering (<a href="/courses/c11236.html">C11236</a>), the Graduate Diploma in Engineering, the Master of Engineering (<a href="/courses/c04271.html">C04271</a>), the Master of Engineering (Extension) (<a href="/courses/c04277.html">C04277</a>), the Master of Engineering (Advanced) (<a href="/courses/c04278.html">C04278</a>) and the Master of Engineering Master of Engineering Management (<a href="/courses/c04273.html">C04273</a>).</p>
A58: C03012 | B58: 2025.01 | C58: Master of Design (Research) | D58: A
A59: C03001 | B59: 2025.01 | C59: Master of Architecture (Research) | D59: A
A60: C03002 | B60: 2025.01 | C60: Master of Built Environment (Research) | D60: A
A61: C30019 | B61: 2025.01 | C61: UTS Foundation Studies (Standard) | D61: SN
A62: C06110 | B62: 2025.01 | C62: Graduate Diploma in Engineering Management | D62: D | G62: <p>This exit-only course is part of an articulated program comprising the Graduate Certificate in Engineering Management (<a href="/courses/c11239.html">C11239</a>), the Gradaute Diploma in Engineering Management, the Master of Engineering Management (<a href="/courses/c04275.html">C04275</a>), the Master of Engineering Master of Engineering Management (<a href="/courses/c04273.html">C04273</a>) and the Master of Engineering Management Master of Business Administration (<a href="/courses/c04274.html">C04274</a>).</p>
A63: C04275 | B63: 2025.01 | C63: Master of Engineering Management | D63: D | G63: <p>This course is part of an articulated program comprising the Graduate Certificate in Engineering Management (<a href="/courses/c11239.html">C11239</a>), the Graduate Diploma in Engineering Management (<a href="/courses/c06110.html">C06110</a>) and the Master of Engineering Management.</p>
A64: C11239 | B64: 2025.01 | C64: Graduate Certificate in Engineering Management | D64: D | G64: <p>This course is part of an articulated program comprising the Graduate Certificate in Engineering Management, the Graduate Diploma in Engineering Management (<a href="/courses/c06110.html">C06110</a>) and the Master of Engineering Management (<a href="/courses/c04275.html">C04275</a>).</p>
A65: C11236 | B65: 2025.01 | C65: Graduate Certificate in Engineering | D65: D | G65: <p>This course is part of an articulated program comprising the Graduate Certificate in Engineering, the Graduate Diploma in Engineering (<a href="/courses/c06108.html">C06108</a>), the Master of Engineering (<a href="/courses/c04271.html">C04271</a>) and the Master of Engineering (Extension) (<a href="/courses/c04277.html">C04277</a>).</p>
A66: C04270 | B66: 2025.01 | C66: Master of Landscape Architecture | D66: A
A67: C11238 | B67: 2025.01 | C67: Graduate Certificate in Engineering Studies | D67: D
A68: C11267 | B68: 2025.01 | C68: Graduate Certificate in High Performance Sport | D68: J | G68: <p>This course is part of an articulated program made up of the Graduate Certificate in High Performance Sport (<a href="https://handbook.uts.edu.au/courses/c11267.html">C11267</a>), the Graduate Diploma in High Performance Sport (<a href="https://handbook.uts.edu.au/courses/c07130.html">C07130</a>), and the Master of High Performance Sport (<a 4href="https://handbook.uts.edu.au/courses/c04362.html">C04362</a>).</p>
A69: C07130 | B69: 2025.01 | C69: Graduate Diploma in High Performance Sport | D69: J | G69: <p>This course is part of an articulated program made up of the Graduate Certificate in High Performance Sport (<a href="https://handbook.uts.edu.au/courses/c11267.html">C11267</a>), the Graduate Diploma in High Performance Sport (<a href="https://handbook.uts.edu.au/courses/c07130.html">C07130</a>), and the Master of High Performance Sport (<a href="https://handbook.uts.edu.au/courses/c04362.html">C04362</a>).</p>
A70: C04273 | B70: 2025.01 | C70: Master of Engineering Master of Engineering Management | D70: D | G70: <p>This course is part of an articulated program comprising the Graduate Certificate in Engineering (<a href="/courses/c11236.html">C11236</a>), the Graduate Diploma in Engineering (<a href="/courses/c06108.html">C06108</a>), the Master of Engineering (<a href="/courses/c04271.html">C04271</a>), the Master of Engineering (Extension) (<a href="/courses/c04277.html">C04277</a>) and the Master of Engineering Master of Engineering Management.</p>
A71: C03032 | B71: 2025.01 | C71: Master of Sustainable Futures (Research) | D71: PF
A72: C11115 | B72: 2025.01 | C72: Graduate Certificate in Diabetes Education and Management | D72: J
A73: C30020 | B73: 2025.01 | C73: UTS Foundation Studies (Extended) | D73: SN
A74: C04271 | B74: 2025.01 | C74: Master of Engineering | D74: D | G74: <p>This course is part of an articulated program comprising the Graduate Certificate in Engineering (<a href="/courses/c11236.html">C11236</a>), the Graduate Diploma in Engineering (<a href="/courses/c06108.html">C06108</a>), the Master of Engineering, the Master of Engineering (Extension) (<a href="/courses/c04277.html">C04277</a>) and the Master of Engineering (Advanced) (<a href="/courses/c04278.html">C04278</a>).</p>
A75: C03024 | B75: 2025.01 | C75: Master of Laws (Research) | D75: L
A76: C03026 | B76: 2025.01 | C76: Master of Science (Research) in Mathematical Sciences | D76: N
A77: C03029 | B77: 2025.01 | C77: Master of Science (Research) | D77: N
A78: C09057 | B78: 2025.01 | C78: Bachelor of Sport and Exercise Science (Honours) | D78: J
A79: C04362 | B79: 2025.01 | C79: Master of High Performance Sport | D79: J | G79: <p>This course is part of an articulated program made up of the Graduate Certificate in High Performance Sport (<a href="https://handbook.uts.edu.au/courses/c11267.html">C11267</a>), the Graduate Diploma in High Performance Sport (<a href="https://handbook.uts.edu.au/courses/c07130.html">C07130</a>), and the Master of High Performance Sport (<a href="https://handbook.uts.edu.au/courses/c04362.html">C04362</a>).</p>
A80: C11247 | B80: 2025.01 | C80: Graduate Certificate in Information Technology Studies | D80: D | G80: <p>This course is part of an articulated program comprising the Graduate Certificate in Information Technology Studies, and the Master of Information Technology (<a href="/courses/c04295.html">C04295</a>).</p>
A81: C41010 | B81: 2025.01 | C81: Communication UG Cross-Institution | D81: G
...

Sheet Vlookup- Do not delete
A1: Course Code | B1: Course Name | C1: Owning Faculty
A2: C01001 | B2: Doctor of Letters | C2: P
A3: C01002 | B3: Doctor of Fine Arts | C3: P
A4: C01003 | B4: Doctor of Science | C4: P
A5: C01004 | B5: Doctor of Laws | C5: P
A6: C42003 | B6: Business Postgraduate Cross - Institution | C6: B
A7: C42004 | B7: Design PG Cross Institution | C7: AD
A8: C42005 | B8: Engineering PG Cross-Institution | C8: D
A9: C42013 | B9: International Studies PG Cross-Institution | C9: G
A10: C50002 | B10: Non-Award | C10: P
A11: C30010 | B11: Supplementary Course for Aboriginal Students | C11: PA
A12: C41001 | B12: Architecture Cross UG Cross-Institution | C12: AA
... A668: C09089 | B668: Bachelor of Communication (Writing and Publishing) Bachelor of Laws (Honours) | C668: L
